Workbook

Sheet Read me
A1: Lab 7 coding sheet: Aguirre et al. (2015), Study 2, coded into Eisend et al.'s (2026) scheme
A3: One row per effect (E1–E6), one column per coding field. Columns A–C say what to code; do not change them.
A4: Row 2 of each coding tab says what goes in each column. Every cell is text: type values exactly as printed.
A6: 1. 'My coding' (by hand, before any AI sees the paper). Fill every cell, or write 'not reported' and say why in notes.
A7: Never enter zero or a number you calculated. Dropdowns are suggestions; you may type something else.
A8: 2. 'Codex'. Give Codex a BLANK copy of this file (a fresh download, never your filled copy), the Aguirre PDF and
A9: Eisend et al.'s Table 3. Ask it to fill rows 3–8 of its 'Codex' tab. Then copy those rows into the 'Codex' tab of
A10: your file (columns D onward, rows 3–8).
A11: 3. 'Compare' fills itself and marks every field where you and Codex differ (DIFF, shaded). For each DIFF, go to the page,
A12: record the page that settled it and who was right. Matches still need a page check on anything you were unsure of.
A13: 4. Submit this file (Lab7_YourName_coding.xlsx) with your Word template on Canvas.
A15: Field names match Eisend et al.'s published file where the two overlap (outcome_label, operationalization, items,
... A17: Codebook: Lab 7 hub card, Appendix C.

Sheet My coding
A1: effect_id | B1: outcome_to_code | C1: condition | D1: outcome_label | E1: operationalization | F1: items | G1: scale_points | H1: reliability | I1: category | J1: mean_control | K1: mean_treatment | L1: statistic | M1: stat_value | N1: df | O1: n_effect | P1: n_source | Q1: direction | R1: p_as_printed | S1: where_printed | T1: printed_page | U1: row_decision | V1: notes
A2: Given: do not change | B2: Given: do not change | C2: Given: do not change | D2: Outcome as the authors label it | E2: Item wording, copied (first item + count is fine for multi-item scales) | F2: Number of items | G2: Scale points, or 'not stated' | H2: Alpha as printed, 'single item' or 'not reported' | I2: Eisend Table 3: code and name, or 'manipulation check' | J2: Less personalized mean, as printed | K2: More personalized mean, as printed | L2: Test type | M2: Value exactly as printed (keep the sign) | N2: df for this comparison | O2: N for this comparison | P2: 'printed', or your assumption and where it came from | Q2: From the means | R2: Exact or '< .001' | S2: Where the values appear | T2: Journal page, not the PDF counter | U2: Enter, or the flag | V2: Flag reason, open question, or what you checked
A3: E1 | B3: Manipulation check: perceived personalization | C3: All conditions
A4: E2 | B4: Click-through intentions | C4: Facebook · overt
A5: E3 | B5: Click-through intentions | C5: Facebook · covert
A6: E4 | B6: Click-through intentions | C6: CNN · overt
A7: E5 | B7: Click-through intentions | C7: CNN · covert
A8: E6 | B8: Perceived vulnerability | C8: Facebook · covert

Sheet Codex
A1: effect_id | B1: outcome_to_code | C1: condition | D1: outcome_label | E1: operationalization | F1: items | G1: scale_points | H1: reliability | I1: category | J1: mean_control | K1: mean_treatment | L1: statistic | M1: stat_value | N1: df | O1: n_effect | P1: n_source | Q1: direction | R1: p_as_printed | S1: where_printed | T1: printed_page | U1: row_decision | V1: notes
A2: Given: do not change | B2: Given: do not change | C2: Given: do not change | D2: Outcome as the authors label it | E2: Item wording, copied (first item + count is fine for multi-item scales) | F2: Number of items | G2: Scale points, or 'not stated' | H2: Alpha as printed, 'single item' or 'not reported' | I2: Eisend Table 3: code and name, or 'manipulation check' | J2: Less personalized mean, as printed | K2: More personalized mean, as printed | L2: Test type | M2: Value exactly as printed (keep the sign) | N2: df for this comparison | O2: N for this comparison | P2: 'printed', or your assumption and where it came from | Q2: From the means | R2: Exact or '< .001' | S2: Where the values appear | T2: Journal page, not the PDF counter | U2: Enter, or the flag | V2: Flag reason, open question, or what you checked
A3: E1 | B3: Manipulation check: perceived personalization | C3: All conditions
A4: E2 | B4: Click-through intentions | C4: Facebook · overt
A5: E3 | B5: Click-through intentions | C5: Facebook · covert
A6: E4 | B6: Click-through intentions | C6: CNN · overt
A7: E5 | B7: Click-through intentions | C7: CNN · covert
A8: E6 | B8: Perceived vulnerability | C8: Facebook · covert

Sheet Compare
A1: Compare: filled automatically from 'My coding' and 'Codex'. Settle every DIFF on the page of the article.
A2: Fields compared | B2: =COUNTIF(E5:E118,"match")+COUNTIF(E5:E118,"DIFF") | C2: Matched | D2: =COUNTIF(E5:E118,"match")
A4: effect_id | B4: field | C4: my_entry | D4: codex_entry | E4: result | F4: page_that_settled_it | G4: who_was_right
A5: E1 | B5: outcome_label | C5: =IF('My coding'!D3="","",'My coding'!D3) | D5: =IF(Codex!D3="","",Codex!D3) | E5: =IF(AND('My coding'!D3="",Codex!D3=""),"",IF(TRIM(LOWER('My coding'!D3&""))=TRIM(LOWER(Codex!D3&"")),"match","DIFF"))
A6: E1 | B6: operationalization | C6: =IF('My coding'!E3="","",'My coding'!E3) | D6: =IF(Codex!E3="","",Codex!E3) | E6: =IF(AND('My coding'!E3="",Codex!E3=""),"",IF(TRIM(LOWER('My coding'!E3&""))=TRIM(LOWER(Codex!E3&"")),"match","DIFF"))
A7: E1 | B7: items | C7: =IF('My coding'!F3="","",'My coding'!F3) | D7: =IF(Codex!F3="","",Codex!F3) | E7: =IF(AND('My coding'!F3="",Codex!F3=""),"",IF(TRIM(LOWER('My coding'!F3&""))=TRIM(LOWER(Codex!F3&"")),"match","DIFF"))
A8: E1 | B8: scale_points | C8: =IF('My coding'!G3="","",'My coding'!G3) | D8: =IF(Codex!G3="","",Codex!G3) | E8: =IF(AND('My coding'!G3="",Codex!G3=""),"",IF(TRIM(LOWER('My coding'!G3&""))=TRIM(LOWER(Codex!G3&"")),"match","DIFF"))
A9: E1 | B9: reliability | C9: =IF('My coding'!H3="","",'My coding'!H3) | D9: =IF(Codex!H3="","",Codex!H3) | E9: =IF(AND('My coding'!H3="",Codex!H3=""),"",IF(TRIM(LOWER('My coding'!H3&""))=TRIM(LOWER(Codex!H3&"")),"match","DIFF"))
A10: E1 | B10: category | C10: =IF('My coding'!I3="","",'My coding'!I3) | D10: =IF(Codex!I3="","",Codex!I3) | E10: =IF(AND('My coding'!I3="",Codex!I3=""),"",IF(TRIM(LOWER('My coding'!I3&""))=TRIM(LOWER(Codex!I3&"")),"match","DIFF"))
A11: E1 | B11: mean_control | C11: =IF('My coding'!J3="","",'My coding'!J3) | D11: =IF(Codex!J3="","",Codex!J3) | E11: =IF(AND('My coding'!J3="",Codex!J3=""),"",IF(TRIM(LOWER('My coding'!J3&""))=TRIM(LOWER(Codex!J3&"")),"match","DIFF"))
A12: E1 | B12: mean_treatment | C12: =IF('My coding'!K3="","",'My coding'!K3) | D12: =IF(Codex!K3="","",Codex!K3) | E12: =IF(AND('My coding'!K3="",Codex!K3=""),"",IF(TRIM(LOWER('My coding'!K3&""))=TRIM(LOWER(Codex!K3&"")),"match","DIFF"))
A13: E1 | B13: statistic | C13: =IF('My coding'!L3="","",'My coding'!L3) | D13: =IF(Codex!L3="","",Codex!L3) | E13: =IF(AND('My coding'!L3="",Codex!L3=""),"",IF(TRIM(LOWER('My coding'!L3&""))=TRIM(LOWER(Codex!L3&"")),"match","DIFF"))
A14: E1 | B14: stat_value | C14: =IF('My coding'!M3="","",'My coding'!M3) | D14: =IF(Codex!M3="","",Codex!M3) | E14: =IF(AND('My coding'!M3="",Codex!M3=""),"",IF(TRIM(LOWER('My coding'!M3&""))=TRIM(LOWER(Codex!M3&"")),"match","DIFF"))
A15: E1 | B15: df | C15: =IF('My coding'!N3="","",'My coding'!N3) | D15: =IF(Codex!N3="","",Codex!N3) | E15: =IF(AND('My coding'!N3="",Codex!N3=""),"",IF(TRIM(LOWER('My coding'!N3&""))=TRIM(LOWER(Codex!N3&"")),"match","DIFF"))
A16: E1 | B16: n_effect | C16: =IF('My coding'!O3="","",'My coding'!O3) | D16: =IF(Codex!O3="","",Codex!O3) | E16: =IF(AND('My coding'!O3="",Codex!O3=""),"",IF(TRIM(LOWER('My coding'!O3&""))=TRIM(LOWER(Codex!O3&"")),"match","DIFF"))
A17: E1 | B17: n_source | C17: =IF('My coding'!P3="","",'My coding'!P3) | D17: =IF(Codex!P3="","",Codex!P3) | E17: =IF(AND('My coding'!P3="",Codex!P3=""),"",IF(TRIM(LOWER('My coding'!P3&""))=TRIM(LOWER(Codex!P3&"")),"match","DIFF"))
A18: E1 | B18: direction | C18: =IF('My coding'!Q3="","",'My coding'!Q3) | D18: =IF(Codex!Q3="","",Codex!Q3) | E18: =IF(AND('My coding'!Q3="",Codex!Q3=""),"",IF(TRIM(LOWER('My coding'!Q3&""))=TRIM(LOWER(Codex!Q3&"")),"match","DIFF"))
A19: E1 | B19: p_as_printed | C19: =IF('My coding'!R3="","",'My coding'!R3) | D19: =IF(Codex!R3="","",Codex!R3) | E19: =IF(AND('My coding'!R3="",Codex!R3=""),"",IF(TRIM(LOWER('My coding'!R3&""))=TRIM(LOWER(Codex!R3&"")),"match","DIFF"))
A20: E1 | B20: where_printed | C20: =IF('My coding'!S3="","",'My coding'!S3) | D20: =IF(Codex!S3="","",Codex!S3) | E20: =IF(AND('My coding'!S3="",Codex!S3=""),"",IF(TRIM(LOWER('My coding'!S3&""))=TRIM(LOWER(Codex!S3&"")),"match","DIFF"))
A21: E1 | B21: printed_page | C21: =IF('My coding'!T3="","",'My coding'!T3) | D21: =IF(Codex!T3="","",Codex!T3) | E21: =IF(AND('My coding'!T3="",Codex!T3=""),"",IF(TRIM(LOWER('My coding'!T3&""))=TRIM(LOWER(Codex!T3&"")),"match","DIFF"))
A22: E1 | B22: row_decision | C22: =IF('My coding'!U3="","",'My coding'!U3) | D22: =IF(Codex!U3="","",Codex!U3) | E22: =IF(AND('My coding'!U3="",Codex!U3=""),"",IF(TRIM(LOWER('My coding'!U3&""))=TRIM(LOWER(Codex!U3&"")),"match","DIFF"))
A23: E1 | B23: notes | C23: =IF('My coding'!V3="","",'My coding'!V3) | D23: =IF(Codex!V3="","",Codex!V3) | E23: =IF(AND('My coding'!V3="",Codex!V3=""),"",IF(TRIM(LOWER('My coding'!V3&""))=TRIM(LOWER(Codex!V3&"")),"match","DIFF"))
A24: E2 | B24: outcome_label | C24: =IF('My coding'!D4="","",'My coding'!D4) | D24: =IF(Codex!D4="","",Codex!D4) | E24: =IF(AND('My coding'!D4="",Codex!D4=""),"",IF(TRIM(LOWER('My coding'!D4&""))=TRIM(LOWER(Codex!D4&"")),"match","DIFF"))
A25: E2 | B25: operationalization | C25: =IF('My coding'!E4="","",'My coding'!E4) | D25: =IF(Codex!E4="","",Codex!E4) | E25: =IF(AND('My coding'!E4="",Codex!E4=""),"",IF(TRIM(LOWER('My coding'!E4&""))=TRIM(LOWER(Codex!E4&"")),"match","DIFF"))
A26: E2 | B26: items | C26: =IF('My coding'!F4="","",'My coding'!F4) | D26: =IF(Codex!F4="","",Codex!F4) | E26: =IF(AND('My coding'!F4="",Codex!F4=""),"",IF(TRIM(LOWER('My coding'!F4&""))=TRIM(LOWER(Codex!F4&"")),"match","DIFF"))
A27: E2 | B27: scale_points | C27: =IF('My coding'!G4="","",'My coding'!G4) | D27: =IF(Codex!G4="","",Codex!G4) | E27: =IF(AND('My coding'!G4="",Codex!G4=""),"",IF(TRIM(LOWER('My coding'!G4&""))=TRIM(LOWER(Codex!G4&"")),"match","DIFF"))
A28: E2 | B28: reliability | C28: =IF('My coding'!H4="","",'My coding'!H4) | D28: =IF(Codex!H4="","",Codex!H4) | E28: =IF(AND('My coding'!H4="",Codex!H4=""),"",IF(TRIM(LOWER('My coding'!H4&""))=TRIM(LOWER(Codex!H4&"")),"match","DIFF"))
A29: E2 | B29: category | C29: =IF('My coding'!I4="","",'My coding'!I4) | D29: =IF(Codex!I4="","",Codex!I4) | E29: =IF(AND('My coding'!I4="",Codex!I4=""),"",IF(TRIM(LOWER('My coding'!I4&""))=TRIM(LOWER(Codex!I4&"")),"match","DIFF"))
A30: E2 | B30: mean_control | C30: =IF('My coding'!J4="","",'My coding'!J4) | D30: =IF(Codex!J4="","",Codex!J4) | E30: =IF(AND('My coding'!J4="",Codex!J4=""),"",IF(TRIM(LOWER('My coding'!J4&""))=TRIM(LOWER(Codex!J4&"")),"match","DIFF"))
A31: E2 | B31: mean_treatment | C31: =IF('My coding'!K4="","",'My coding'!K4) | D31: =IF(Codex!K4="","",Codex!K4) | E31: =IF(AND('My coding'!K4="",Codex!K4=""),"",IF(TRIM(LOWER('My coding'!K4&""))=TRIM(LOWER(Codex!K4&"")),"match","DIFF"))
A32: E2 | B32: statistic | C32: =IF('My coding'!L4="","",'My coding'!L4) | D32: =IF(Codex!L4="","",Codex!L4) | E32: =IF(AND('My coding'!L4="",Codex!L4=""),"",IF(TRIM(LOWER('My coding'!L4&""))=TRIM(LOWER(Codex!L4&"")),"match","DIFF"))
A33: E2 | B33: stat_value | C33: =IF('My coding'!M4="","",'My coding'!M4) | D33: =IF(Codex!M4="","",Codex!M4) | E33: =IF(AND('My coding'!M4="",Codex!M4=""),"",IF(TRIM(LOWER('My coding'!M4&""))=TRIM(LOWER(Codex!M4&"")),"match","DIFF"))
A34: E2 | B34: df | C34: =IF('My coding'!N4="","",'My coding'!N4) | D34: =IF(Codex!N4="","",Codex!N4) | E34: =IF(AND('My coding'!N4="",Codex!N4=""),"",IF(TRIM(LOWER('My coding'!N4&""))=TRIM(LOWER(Codex!N4&"")),"match","DIFF"))
A35: E2 | B35: n_effect | C35: =IF('My coding'!O4="","",'My coding'!O4) | D35: =IF(Codex!O4="","",Codex!O4) | E35: =IF(AND('My coding'!O4="",Codex!O4=""),"",IF(TRIM(LOWER('My coding'!O4&""))=TRIM(LOWER(Codex!O4&"")),"match","DIFF"))
A36: E2 | B36: n_source | C36: =IF('My coding'!P4="","",'My coding'!P4) | D36: =IF(Codex!P4="","",Codex!P4) | E36: =IF(AND('My coding'!P4="",Codex!P4=""),"",IF(TRIM(LOWER('My coding'!P4&""))=TRIM(LOWER(Codex!P4&"")),"match","DIFF"))
A37: E2 | B37: direction | C37: =IF('My coding'!Q4="","",'My coding'!Q4) | D37: =IF(Codex!Q4="","",Codex!Q4) | E37: =IF(AND('My coding'!Q4="",Codex!Q4=""),"",IF(TRIM(LOWER('My coding'!Q4&""))=TRIM(LOWER(Codex!Q4&"")),"match","DIFF"))
A38: E2 | B38: p_as_printed | C38: =IF('My coding'!R4="","",'My coding'!R4) | D38: =IF(Codex!R4="","",Codex!R4) | E38: =IF(AND('My coding'!R4="",Codex!R4=""),"",IF(TRIM(LOWER('My coding'!R4&""))=TRIM(LOWER(Codex!R4&"")),"match","DIFF"))
A39: E2 | B39: where_printed | C39: =IF('My coding'!S4="","",'My coding'!S4) | D39: =IF(Codex!S4="","",Codex!S4) | E39: =IF(AND('My coding'!S4="",Codex!S4=""),"",IF(TRIM(LOWER('My coding'!S4&""))=TRIM(LOWER(Codex!S4&"")),"match","DIFF"))
A40: E2 | B40: printed_page | C40: =IF('My coding'!T4="","",'My coding'!T4) | D40: =IF(Codex!T4="","",Codex!T4) | E40: =IF(AND('My coding'!T4="",Codex!T4=""),"",IF(TRIM(LOWER('My coding'!T4&""))=TRIM(LOWER(Codex!T4&"")),"match","DIFF"))
A41: E2 | B41: row_decision | C41: =IF('My coding'!U4="","",'My coding'!U4) | D41: =IF(Codex!U4="","",Codex!U4) | E41: =IF(AND('My coding'!U4="",Codex!U4=""),"",IF(TRIM(LOWER('My coding'!U4&""))=TRIM(LOWER(Codex!U4&"")),"match","DIFF"))
...
